5と想定する。\
tryには`throw Error()`があるため、catchブロックが実行される。\
しかし、最後にはfinallyブロックが必ず実行されるため、continueになるので、\
i=5までループが実行されて、xは5になる。

実行して、結果が5になった。